2022-08-22 21:48:03,376 -  nornir.core -     INFO -        run() - Running task 'send_command' with args {'command': 'show ntp config'} on 1 hosts
2022-08-22 21:48:03,383 - nornir.core.task -    ERROR -      start() - Host 'R1': task 'send_command' failed with traceback:
Traceback (most recent call last):
  File "C:\Projects\zero_touch\api\.venv\lib\site-packages\nornir\core\task.py", line 99, in start
    r = self.task(self, **self.params)
  File "C:\Projects\zero_touch\api\.venv\lib\site-packages\nornir_scrapli\tasks\core\send_command.py", line 36, in send_command
    scrapli_conn = task.host.get_connection("scrapli", task.nornir.config)
  File "C:\Projects\zero_touch\api\.venv\lib\site-packages\nornir\core\inventory.py", line 494, in get_connection
    self.open_connection(
  File "C:\Projects\zero_touch\api\.venv\lib\site-packages\nornir\core\inventory.py", line 546, in open_connection
    conn_obj.open(
  File "C:\Projects\zero_touch\api\.venv\lib\site-packages\nornir_scrapli\connection.py", line 98, in open
    connection = Scrapli(**parameters, platform=final_platform)
  File "C:\Projects\zero_touch\api\.venv\lib\site-packages\scrapli\factory.py", line 506, in __new__
    final_conn = final_driver(**final_kwargs)
  File "C:\Projects\zero_touch\api\.venv\lib\site-packages\scrapli\driver\core\cisco_iosxe\sync_driver.py", line 127, in __init__
    super().__init__(
  File "C:\Projects\zero_touch\api\.venv\lib\site-packages\scrapli\driver\network\sync_driver.py", line 48, in __init__
    super().__init__(
  File "C:\Projects\zero_touch\api\.venv\lib\site-packages\scrapli\driver\generic\sync_driver.py", line 47, in __init__
    super().__init__(
  File "C:\Projects\zero_touch\api\.venv\lib\site-packages\scrapli\driver\base\sync_driver.py", line 15, in __init__
    super().__init__(**kwargs)
  File "C:\Projects\zero_touch\api\.venv\lib\site-packages\scrapli\driver\base\base_driver.py", line 187, in __init__
    self.transport = transport_class(
  File "C:\Projects\zero_touch\api\.venv\lib\site-packages\scrapli\transport\plugins\system\transport.py", line 60, in __init__
    raise ScrapliUnsupportedPlatform("system transport is not supported on windows devices")
scrapli.exceptions.ScrapliUnsupportedPlatform: system transport is not supported on windows devices

2022-08-22 21:54:59,504 -  nornir.core -     INFO -        run() - Running task 'send_command' with args {'command': 'show ntp config'} on 1 hosts
2022-08-22 21:55:06,385 -  nornir.core -     INFO -        run() - Running task 'send_command' with args {'command': 'show ntp config'} on 1 hosts
2022-08-22 21:55:06,394 - nornir.core.task -    ERROR -      start() - Host 'R1': task 'send_command' failed with traceback:
Traceback (most recent call last):
  File "C:\Projects\zero_touch\api\.venv\lib\site-packages\nornir\core\task.py", line 99, in start
    r = self.task(self, **self.params)
  File "C:\Projects\zero_touch\api\.venv\lib\site-packages\nornir_scrapli\tasks\core\send_command.py", line 36, in send_command
    scrapli_conn = task.host.get_connection("scrapli", task.nornir.config)
  File "C:\Projects\zero_touch\api\.venv\lib\site-packages\nornir\core\inventory.py", line 494, in get_connection
    self.open_connection(
  File "C:\Projects\zero_touch\api\.venv\lib\site-packages\nornir\core\inventory.py", line 546, in open_connection
    conn_obj.open(
  File "C:\Projects\zero_touch\api\.venv\lib\site-packages\nornir_scrapli\connection.py", line 98, in open
    connection = Scrapli(**parameters, platform=final_platform)
  File "C:\Projects\zero_touch\api\.venv\lib\site-packages\scrapli\factory.py", line 506, in __new__
    final_conn = final_driver(**final_kwargs)
  File "C:\Projects\zero_touch\api\.venv\lib\site-packages\scrapli\driver\core\cisco_iosxe\sync_driver.py", line 127, in __init__
    super().__init__(
  File "C:\Projects\zero_touch\api\.venv\lib\site-packages\scrapli\driver\network\sync_driver.py", line 48, in __init__
    super().__init__(
  File "C:\Projects\zero_touch\api\.venv\lib\site-packages\scrapli\driver\generic\sync_driver.py", line 47, in __init__
    super().__init__(
  File "C:\Projects\zero_touch\api\.venv\lib\site-packages\scrapli\driver\base\sync_driver.py", line 15, in __init__
    super().__init__(**kwargs)
  File "C:\Projects\zero_touch\api\.venv\lib\site-packages\scrapli\driver\base\base_driver.py", line 187, in __init__
    self.transport = transport_class(
  File "C:\Projects\zero_touch\api\.venv\lib\site-packages\scrapli\transport\plugins\system\transport.py", line 60, in __init__
    raise ScrapliUnsupportedPlatform("system transport is not supported on windows devices")
scrapli.exceptions.ScrapliUnsupportedPlatform: system transport is not supported on windows devices

2022-08-22 21:55:41,513 -  nornir.core -     INFO -        run() - Running task 'send_command' with args {'command': 'show ntp config'} on 1 hosts
2022-08-22 21:55:41,520 - nornir.core.task -    ERROR -      start() - Host 'R1': task 'send_command' failed with traceback:
Traceback (most recent call last):
  File "C:\Projects\zero_touch\api\.venv\lib\site-packages\nornir\core\task.py", line 99, in start
    r = self.task(self, **self.params)
  File "C:\Projects\zero_touch\api\.venv\lib\site-packages\nornir_scrapli\tasks\core\send_command.py", line 36, in send_command
    scrapli_conn = task.host.get_connection("scrapli", task.nornir.config)
  File "C:\Projects\zero_touch\api\.venv\lib\site-packages\nornir\core\inventory.py", line 494, in get_connection
    self.open_connection(
  File "C:\Projects\zero_touch\api\.venv\lib\site-packages\nornir\core\inventory.py", line 546, in open_connection
    conn_obj.open(
  File "C:\Projects\zero_touch\api\.venv\lib\site-packages\nornir_scrapli\connection.py", line 98, in open
    connection = Scrapli(**parameters, platform=final_platform)
  File "C:\Projects\zero_touch\api\.venv\lib\site-packages\scrapli\factory.py", line 506, in __new__
    final_conn = final_driver(**final_kwargs)
  File "C:\Projects\zero_touch\api\.venv\lib\site-packages\scrapli\driver\core\cisco_iosxe\sync_driver.py", line 127, in __init__
    super().__init__(
  File "C:\Projects\zero_touch\api\.venv\lib\site-packages\scrapli\driver\network\sync_driver.py", line 48, in __init__
    super().__init__(
  File "C:\Projects\zero_touch\api\.venv\lib\site-packages\scrapli\driver\generic\sync_driver.py", line 47, in __init__
    super().__init__(
  File "C:\Projects\zero_touch\api\.venv\lib\site-packages\scrapli\driver\base\sync_driver.py", line 15, in __init__
    super().__init__(**kwargs)
  File "C:\Projects\zero_touch\api\.venv\lib\site-packages\scrapli\driver\base\base_driver.py", line 187, in __init__
    self.transport = transport_class(
  File "C:\Projects\zero_touch\api\.venv\lib\site-packages\scrapli\transport\plugins\system\transport.py", line 60, in __init__
    raise ScrapliUnsupportedPlatform("system transport is not supported on windows devices")
scrapli.exceptions.ScrapliUnsupportedPlatform: system transport is not supported on windows devices

2022-08-22 21:56:13,849 -  nornir.core -     INFO -        run() - Running task 'send_command' with args {'command': 'show ntp config'} on 1 hosts
2022-08-22 21:56:13,857 - nornir.core.task -    ERROR -      start() - Host 'R1': task 'send_command' failed with traceback:
Traceback (most recent call last):
  File "C:\Projects\zero_touch\api\.venv\lib\site-packages\nornir\core\task.py", line 99, in start
    r = self.task(self, **self.params)
  File "C:\Projects\zero_touch\api\.venv\lib\site-packages\nornir_scrapli\tasks\core\send_command.py", line 36, in send_command
    scrapli_conn = task.host.get_connection("scrapli", task.nornir.config)
  File "C:\Projects\zero_touch\api\.venv\lib\site-packages\nornir\core\inventory.py", line 494, in get_connection
    self.open_connection(
  File "C:\Projects\zero_touch\api\.venv\lib\site-packages\nornir\core\inventory.py", line 546, in open_connection
    conn_obj.open(
  File "C:\Projects\zero_touch\api\.venv\lib\site-packages\nornir_scrapli\connection.py", line 98, in open
    connection = Scrapli(**parameters, platform=final_platform)
  File "C:\Projects\zero_touch\api\.venv\lib\site-packages\scrapli\factory.py", line 506, in __new__
    final_conn = final_driver(**final_kwargs)
  File "C:\Projects\zero_touch\api\.venv\lib\site-packages\scrapli\driver\core\cisco_iosxe\sync_driver.py", line 127, in __init__
    super().__init__(
  File "C:\Projects\zero_touch\api\.venv\lib\site-packages\scrapli\driver\network\sync_driver.py", line 48, in __init__
    super().__init__(
  File "C:\Projects\zero_touch\api\.venv\lib\site-packages\scrapli\driver\generic\sync_driver.py", line 47, in __init__
    super().__init__(
  File "C:\Projects\zero_touch\api\.venv\lib\site-packages\scrapli\driver\base\sync_driver.py", line 15, in __init__
    super().__init__(**kwargs)
  File "C:\Projects\zero_touch\api\.venv\lib\site-packages\scrapli\driver\base\base_driver.py", line 187, in __init__
    self.transport = transport_class(
  File "C:\Projects\zero_touch\api\.venv\lib\site-packages\scrapli\transport\plugins\system\transport.py", line 60, in __init__
    raise ScrapliUnsupportedPlatform("system transport is not supported on windows devices")
scrapli.exceptions.ScrapliUnsupportedPlatform: system transport is not supported on windows devices

2022-08-22 21:57:06,265 -  nornir.core -     INFO -        run() - Running task 'send_command' with args {'command': 'show ntp config'} on 1 hosts
2022-08-22 21:57:06,272 - nornir.core.task -    ERROR -      start() - Host 'R1': task 'send_command' failed with traceback:
Traceback (most recent call last):
  File "C:\Projects\zero_touch\api\.venv\lib\site-packages\nornir\core\task.py", line 99, in start
    r = self.task(self, **self.params)
  File "C:\Projects\zero_touch\api\.venv\lib\site-packages\nornir_scrapli\tasks\core\send_command.py", line 36, in send_command
    scrapli_conn = task.host.get_connection("scrapli", task.nornir.config)
  File "C:\Projects\zero_touch\api\.venv\lib\site-packages\nornir\core\inventory.py", line 494, in get_connection
    self.open_connection(
  File "C:\Projects\zero_touch\api\.venv\lib\site-packages\nornir\core\inventory.py", line 546, in open_connection
    conn_obj.open(
  File "C:\Projects\zero_touch\api\.venv\lib\site-packages\nornir_scrapli\connection.py", line 98, in open
    connection = Scrapli(**parameters, platform=final_platform)
  File "C:\Projects\zero_touch\api\.venv\lib\site-packages\scrapli\factory.py", line 506, in __new__
    final_conn = final_driver(**final_kwargs)
  File "C:\Projects\zero_touch\api\.venv\lib\site-packages\scrapli\driver\core\cisco_iosxe\sync_driver.py", line 127, in __init__
    super().__init__(
  File "C:\Projects\zero_touch\api\.venv\lib\site-packages\scrapli\driver\network\sync_driver.py", line 48, in __init__
    super().__init__(
  File "C:\Projects\zero_touch\api\.venv\lib\site-packages\scrapli\driver\generic\sync_driver.py", line 47, in __init__
    super().__init__(
  File "C:\Projects\zero_touch\api\.venv\lib\site-packages\scrapli\driver\base\sync_driver.py", line 15, in __init__
    super().__init__(**kwargs)
  File "C:\Projects\zero_touch\api\.venv\lib\site-packages\scrapli\driver\base\base_driver.py", line 187, in __init__
    self.transport = transport_class(
  File "C:\Projects\zero_touch\api\.venv\lib\site-packages\scrapli\transport\plugins\system\transport.py", line 60, in __init__
    raise ScrapliUnsupportedPlatform("system transport is not supported on windows devices")
scrapli.exceptions.ScrapliUnsupportedPlatform: system transport is not supported on windows devices

2022-08-22 22:06:40,311 -  nornir.core -     INFO -        run() - Running task 'send_command' with args {'command': 'show ntp config'} on 1 hosts
2022-08-22 22:06:40,318 - nornir.core.task -    ERROR -      start() - Host 'R1': task 'send_command' failed with traceback:
Traceback (most recent call last):
  File "C:\Projects\zero_touch\api\.venv\lib\site-packages\nornir\core\task.py", line 99, in start
    r = self.task(self, **self.params)
  File "C:\Projects\zero_touch\api\.venv\lib\site-packages\nornir_scrapli\tasks\core\send_command.py", line 36, in send_command
    scrapli_conn = task.host.get_connection("scrapli", task.nornir.config)
  File "C:\Projects\zero_touch\api\.venv\lib\site-packages\nornir\core\inventory.py", line 494, in get_connection
    self.open_connection(
  File "C:\Projects\zero_touch\api\.venv\lib\site-packages\nornir\core\inventory.py", line 546, in open_connection
    conn_obj.open(
  File "C:\Projects\zero_touch\api\.venv\lib\site-packages\nornir_scrapli\connection.py", line 98, in open
    connection = Scrapli(**parameters, platform=final_platform)
  File "C:\Projects\zero_touch\api\.venv\lib\site-packages\scrapli\factory.py", line 506, in __new__
    final_conn = final_driver(**final_kwargs)
  File "C:\Projects\zero_touch\api\.venv\lib\site-packages\scrapli\driver\core\cisco_iosxe\sync_driver.py", line 127, in __init__
    super().__init__(
  File "C:\Projects\zero_touch\api\.venv\lib\site-packages\scrapli\driver\network\sync_driver.py", line 48, in __init__
    super().__init__(
  File "C:\Projects\zero_touch\api\.venv\lib\site-packages\scrapli\driver\generic\sync_driver.py", line 47, in __init__
    super().__init__(
  File "C:\Projects\zero_touch\api\.venv\lib\site-packages\scrapli\driver\base\sync_driver.py", line 15, in __init__
    super().__init__(**kwargs)
  File "C:\Projects\zero_touch\api\.venv\lib\site-packages\scrapli\driver\base\base_driver.py", line 187, in __init__
    self.transport = transport_class(
  File "C:\Projects\zero_touch\api\.venv\lib\site-packages\scrapli\transport\plugins\system\transport.py", line 60, in __init__
    raise ScrapliUnsupportedPlatform("system transport is not supported on windows devices")
scrapli.exceptions.ScrapliUnsupportedPlatform: system transport is not supported on windows devices

2022-08-22 22:16:58,599 -  nornir.core -     INFO -        run() - Running task 'send_command' with args {'command': 'show version '} on 1 hosts
2022-08-22 22:16:58,605 - nornir.core.task -    ERROR -      start() - Host 'R1': task 'send_command' failed with traceback:
Traceback (most recent call last):
  File "C:\Projects\zero_touch\api\.venv\lib\site-packages\nornir\core\task.py", line 99, in start
    r = self.task(self, **self.params)
  File "C:\Projects\zero_touch\api\.venv\lib\site-packages\nornir_scrapli\tasks\core\send_command.py", line 36, in send_command
    scrapli_conn = task.host.get_connection("scrapli", task.nornir.config)
  File "C:\Projects\zero_touch\api\.venv\lib\site-packages\nornir\core\inventory.py", line 494, in get_connection
    self.open_connection(
  File "C:\Projects\zero_touch\api\.venv\lib\site-packages\nornir\core\inventory.py", line 546, in open_connection
    conn_obj.open(
  File "C:\Projects\zero_touch\api\.venv\lib\site-packages\nornir_scrapli\connection.py", line 98, in open
    connection = Scrapli(**parameters, platform=final_platform)
  File "C:\Projects\zero_touch\api\.venv\lib\site-packages\scrapli\factory.py", line 506, in __new__
    final_conn = final_driver(**final_kwargs)
  File "C:\Projects\zero_touch\api\.venv\lib\site-packages\scrapli\driver\core\cisco_iosxe\sync_driver.py", line 127, in __init__
    super().__init__(
  File "C:\Projects\zero_touch\api\.venv\lib\site-packages\scrapli\driver\network\sync_driver.py", line 48, in __init__
    super().__init__(
  File "C:\Projects\zero_touch\api\.venv\lib\site-packages\scrapli\driver\generic\sync_driver.py", line 47, in __init__
    super().__init__(
  File "C:\Projects\zero_touch\api\.venv\lib\site-packages\scrapli\driver\base\sync_driver.py", line 15, in __init__
    super().__init__(**kwargs)
  File "C:\Projects\zero_touch\api\.venv\lib\site-packages\scrapli\driver\base\base_driver.py", line 187, in __init__
    self.transport = transport_class(
  File "C:\Projects\zero_touch\api\.venv\lib\site-packages\scrapli\transport\plugins\system\transport.py", line 60, in __init__
    raise ScrapliUnsupportedPlatform("system transport is not supported on windows devices")
scrapli.exceptions.ScrapliUnsupportedPlatform: system transport is not supported on windows devices

2022-08-22 22:23:02,885 -  nornir.core -     INFO -        run() - Running task 'send_command' with args {'command': 'show version '} on 1 hosts
2022-08-22 22:23:02,893 - nornir.core.task -    ERROR -      start() - Host 'R1': task 'send_command' failed with traceback:
Traceback (most recent call last):
  File "C:\Projects\zero_touch\api\.venv\lib\site-packages\nornir\core\task.py", line 99, in start
    r = self.task(self, **self.params)
  File "C:\Projects\zero_touch\api\.venv\lib\site-packages\nornir_scrapli\tasks\core\send_command.py", line 36, in send_command
    scrapli_conn = task.host.get_connection("scrapli", task.nornir.config)
  File "C:\Projects\zero_touch\api\.venv\lib\site-packages\nornir\core\inventory.py", line 494, in get_connection
    self.open_connection(
  File "C:\Projects\zero_touch\api\.venv\lib\site-packages\nornir\core\inventory.py", line 546, in open_connection
    conn_obj.open(
  File "C:\Projects\zero_touch\api\.venv\lib\site-packages\nornir_scrapli\connection.py", line 98, in open
    connection = Scrapli(**parameters, platform=final_platform)
  File "C:\Projects\zero_touch\api\.venv\lib\site-packages\scrapli\factory.py", line 506, in __new__
    final_conn = final_driver(**final_kwargs)
  File "C:\Projects\zero_touch\api\.venv\lib\site-packages\scrapli\driver\core\cisco_iosxe\sync_driver.py", line 127, in __init__
    super().__init__(
  File "C:\Projects\zero_touch\api\.venv\lib\site-packages\scrapli\driver\network\sync_driver.py", line 48, in __init__
    super().__init__(
  File "C:\Projects\zero_touch\api\.venv\lib\site-packages\scrapli\driver\generic\sync_driver.py", line 47, in __init__
    super().__init__(
  File "C:\Projects\zero_touch\api\.venv\lib\site-packages\scrapli\driver\base\sync_driver.py", line 15, in __init__
    super().__init__(**kwargs)
  File "C:\Projects\zero_touch\api\.venv\lib\site-packages\scrapli\driver\base\base_driver.py", line 187, in __init__
    self.transport = transport_class(
  File "C:\Projects\zero_touch\api\.venv\lib\site-packages\scrapli\transport\plugins\system\transport.py", line 60, in __init__
    raise ScrapliUnsupportedPlatform("system transport is not supported on windows devices")
scrapli.exceptions.ScrapliUnsupportedPlatform: system transport is not supported on windows devices

2022-08-22 22:29:30,358 -  nornir.core -     INFO -        run() - Running task 'another_show_command_test' with args {} on 1 hosts
2022-08-22 22:33:52,970 -  nornir.core -     INFO -        run() - Running task 'another_show_command_test' with args {} on 1 hosts
2022-08-22 22:33:54,072 - nornir.core.task -    ERROR -      start() - Host 'R1': task 'another_show_command_test' failed with traceback:
Traceback (most recent call last):
  File "C:\Projects\zero_touch\api\.venv\lib\site-packages\nornir\core\task.py", line 99, in start
    r = self.task(self, **self.params)
  File "C:\Projects\zero_touch\api\zero_backend\zero_touch_api\views.py", line 22, in another_show_command_test
    task.host["facts"] = interfaces_result.genie_parse_output()
  File "C:\Projects\zero_touch\api\.venv\lib\site-packages\nornir\core\task.py", line 255, in __getattr__
    return getattr(self[0], name)
AttributeError: 'Result' object has no attribute 'genie_parse_output'

2022-08-22 22:34:25,887 -  nornir.core -     INFO -        run() - Running task 'another_show_command_test' with args {} on 1 hosts
2022-08-22 22:34:26,709 - nornir.core.task -    ERROR -      start() - Host 'R1': task 'another_show_command_test' failed with traceback:
Traceback (most recent call last):
  File "C:\Projects\zero_touch\api\.venv\lib\site-packages\nornir\core\task.py", line 99, in start
    r = self.task(self, **self.params)
  File "C:\Projects\zero_touch\api\zero_backend\zero_touch_api\views.py", line 22, in another_show_command_test
    task.host["facts"] = interfaces_result.genie_parse_output()
  File "C:\Projects\zero_touch\api\.venv\lib\site-packages\nornir\core\task.py", line 255, in __getattr__
    return getattr(self[0], name)
AttributeError: 'Result' object has no attribute 'genie_parse_output'

2022-08-22 22:37:51,466 -  nornir.core -     INFO -        run() - Running task 'another_show_command_test' with args {} on 1 hosts
2022-08-22 22:38:33,802 -  nornir.core -     INFO -        run() - Running task 'another_show_command_test' with args {} on 1 hosts
2022-08-22 22:38:34,765 - nornir.core.task -    ERROR -      start() - Host 'R1': task 'another_show_command_test' failed with traceback:
Traceback (most recent call last):
  File "C:\Projects\zero_touch\api\.venv\lib\site-packages\nornir\core\task.py", line 99, in start
    r = self.task(self, **self.params)
  File "C:\Projects\zero_touch\api\zero_backend\zero_touch_api\views.py", line 24, in another_show_command_test
    print(interfaces_result["intf"])
TypeError: list indices must be integers or slices, not str

2022-08-22 23:00:00,106 -  nornir.core -     INFO -        run() - Running task 'another_show_command_test' with args {} on 1 hosts
2022-08-22 23:00:39,030 -  nornir.core -     INFO -        run() - Running task 'another_show_command_test' with args {} on 1 hosts
2022-08-22 23:01:29,270 -  nornir.core -     INFO -        run() - Running task 'another_show_command_test' with args {} on 1 hosts
2022-08-22 23:01:54,294 -  nornir.core -     INFO -        run() - Running task 'another_show_command_test' with args {} on 1 hosts
2022-08-22 23:02:05,018 -  nornir.core -     INFO -        run() - Running task 'another_show_command_test' with args {} on 1 hosts
2022-08-22 23:02:06,272 -  nornir.core -     INFO -        run() - Running task 'another_show_command_test' with args {} on 1 hosts
2022-08-22 23:02:49,648 -  nornir.core -     INFO -        run() - Running task 'another_show_command_test' with args {} on 1 hosts
2022-08-22 23:03:14,587 -  nornir.core -     INFO -        run() - Running task 'another_show_command_test' with args {} on 1 hosts
2022-08-22 23:03:32,870 -  nornir.core -     INFO -        run() - Running task 'another_show_command_test' with args {} on 1 hosts
2022-08-22 23:03:48,962 -  nornir.core -     INFO -        run() - Running task 'another_show_command_test' with args {} on 1 hosts
2022-08-22 23:04:13,358 -  nornir.core -     INFO -        run() - Running task 'another_show_command_test' with args {} on 1 hosts
2022-08-22 23:04:35,834 -  nornir.core -     INFO -        run() - Running task 'another_show_command_test' with args {} on 1 hosts
2022-08-22 23:04:57,476 -  nornir.core -     INFO -        run() - Running task 'another_show_command_test' with args {} on 1 hosts
2022-08-22 23:05:20,968 -  nornir.core -     INFO -        run() - Running task 'another_show_command_test' with args {} on 1 hosts
2022-08-22 23:05:30,523 -  nornir.core -     INFO -        run() - Running task 'another_show_command_test' with args {} on 1 hosts
2022-08-22 23:06:11,092 -  nornir.core -     INFO -        run() - Running task 'another_show_command_test' with args {} on 1 hosts
2022-08-22 23:07:14,174 -  nornir.core -     INFO -        run() - Running task 'another_show_command_test' with args {} on 1 hosts
2022-08-22 23:07:59,159 -  nornir.core -     INFO -        run() - Running task 'another_show_command_test' with args {} on 1 hosts
2022-08-22 23:07:59,980 - nornir.core.task -    ERROR -      start() - Host 'R1': task 'netmiko_send_command' failed with traceback:
Traceback (most recent call last):
  File "C:\Projects\zero_touch\api\.venv\lib\site-packages\nornir\core\task.py", line 99, in start
    r = self.task(self, **self.params)
  File "C:\Projects\zero_touch\api\.venv\lib\site-packages\nornir_netmiko\tasks\netmiko_send_command.py", line 32, in netmiko_send_command
    result = net_connect.send_command(command_string, **kwargs)
  File "C:\Projects\zero_touch\api\.venv\lib\site-packages\netmiko\utilities.py", line 592, in wrapper_decorator
    return func(self, *args, **kwargs)
  File "C:\Projects\zero_touch\api\.venv\lib\site-packages\netmiko\base_connection.py", line 1729, in send_command
    return_val = structured_data_converter(
  File "C:\Projects\zero_touch\api\.venv\lib\site-packages\netmiko\utilities.py", line 577, in structured_data_converter
    structured_output_genie = get_structured_data_genie(
  File "C:\Projects\zero_touch\api\.venv\lib\site-packages\netmiko\utilities.py", line 500, in get_structured_data_genie
    raise ValueError(msg)
ValueError: 
Genie and PyATS are not installed. Please PIP install both Genie and PyATS:
pip install genie
pip install pyats


2022-08-22 23:07:59,981 - nornir.core.task -    ERROR -      start() - Host 'R1': task 'another_show_command_test' failed with traceback:
Traceback (most recent call last):
  File "C:\Projects\zero_touch\api\.venv\lib\site-packages\nornir\core\task.py", line 99, in start
    r = self.task(self, **self.params)
  File "C:\Projects\zero_touch\api\zero_backend\zero_touch_api\views.py", line 19, in another_show_command_test
    interfaces_result = task.run(
  File "C:\Projects\zero_touch\api\.venv\lib\site-packages\nornir\core\task.py", line 174, in run
    raise NornirSubTaskError(task=run_task, result=r)
nornir.core.exceptions.NornirSubTaskError: Subtask: netmiko_send_command (failed)


2022-08-22 23:12:58,665 -  nornir.core -     INFO -        run() - Running task 'another_show_command_test' with args {} on 1 hosts
2022-08-22 23:15:50,326 -  nornir.core -     INFO -        run() - Running task 'another_show_command_test' with args {} on 1 hosts
2022-08-22 23:15:51,479 - nornir.core.task -    ERROR -      start() - Host 'R1': task 'another_show_command_test' failed with traceback:
Traceback (most recent call last):
  File "C:\Projects\zero_touch\api\.venv\lib\site-packages\nornir\core\task.py", line 99, in start
    r = self.task(self, **self.params)
  File "C:\Projects\zero_touch\api\zero_backend\zero_touch_api\views.py", line 25, in another_show_command_test
    print(interfaces_result.result["intf"])
TypeError: list indices must be integers or slices, not str

2022-08-22 23:16:05,532 -  nornir.core -     INFO -        run() - Running task 'another_show_command_test' with args {} on 1 hosts
2022-08-22 23:16:46,489 -  nornir.core -     INFO -        run() - Running task 'another_show_command_test' with args {} on 1 hosts
2022-08-22 23:16:47,735 - nornir.core.task -    ERROR -      start() - Host 'R1': task 'another_show_command_test' failed with traceback:
Traceback (most recent call last):
  File "C:\Projects\zero_touch\api\.venv\lib\site-packages\nornir\core\task.py", line 99, in start
    r = self.task(self, **self.params)
  File "C:\Projects\zero_touch\api\zero_backend\zero_touch_api\views.py", line 25, in another_show_command_test
    print(ast.literal_eval(interfaces_result.result))
NameError: name 'ast' is not defined

2022-08-22 23:17:00,691 -  nornir.core -     INFO -        run() - Running task 'another_show_command_test' with args {} on 1 hosts
2022-08-22 23:17:01,609 - nornir.core.task -    ERROR -      start() - Host 'R1': task 'another_show_command_test' failed with traceback:
Traceback (most recent call last):
  File "C:\Projects\zero_touch\api\.venv\lib\site-packages\nornir\core\task.py", line 99, in start
    r = self.task(self, **self.params)
  File "C:\Projects\zero_touch\api\zero_backend\zero_touch_api\views.py", line 26, in another_show_command_test
    print(ast.literal_eval(interfaces_result.result))
  File "C:\Users\idan5\AppData\Local\Programs\Python\Python310\lib\ast.py", line 108, in literal_eval
    return _convert(node_or_string)
  File "C:\Users\idan5\AppData\Local\Programs\Python\Python310\lib\ast.py", line 107, in _convert
    return _convert_signed_num(node)
  File "C:\Users\idan5\AppData\Local\Programs\Python\Python310\lib\ast.py", line 81, in _convert_signed_num
    return _convert_num(node)
  File "C:\Users\idan5\AppData\Local\Programs\Python\Python310\lib\ast.py", line 72, in _convert_num
    _raise_malformed_node(node)
  File "C:\Users\idan5\AppData\Local\Programs\Python\Python310\lib\ast.py", line 69, in _raise_malformed_node
    raise ValueError(msg + f': {node!r}')
ValueError: malformed node or string: [{'intf': 'Ethernet0/0', 'ipaddr': '192.168.19.101', 'status': 'up', 'proto': 'up'}, {'intf': 'Ethernet0/1', 'ipaddr': 'unassigned', 'status': 'administratively down', 'proto': 'down'}, {'intf': 'Ethernet0/2', 'ipaddr': 'unassigned', 'status': 'administratively down', 'proto': 'down'}, {'intf': 'Ethernet0/3', 'ipaddr': 'unassigned', 'status': 'administratively down', 'proto': 'down'}]

2022-08-22 23:18:28,912 -  nornir.core -     INFO -        run() - Running task 'another_show_command_test' with args {} on 1 hosts
2022-08-22 23:18:30,138 - nornir.core.task -    ERROR -      start() - Host 'R1': task 'another_show_command_test' failed with traceback:
Traceback (most recent call last):
  File "C:\Projects\zero_touch\api\.venv\lib\site-packages\nornir\core\task.py", line 99, in start
    r = self.task(self, **self.params)
  File "C:\Projects\zero_touch\api\zero_backend\zero_touch_api\views.py", line 26, in another_show_command_test
    print(ast.literal_eval(interfaces_result.result[1:-1]))
  File "C:\Users\idan5\AppData\Local\Programs\Python\Python310\lib\ast.py", line 108, in literal_eval
    return _convert(node_or_string)
  File "C:\Users\idan5\AppData\Local\Programs\Python\Python310\lib\ast.py", line 107, in _convert
    return _convert_signed_num(node)
  File "C:\Users\idan5\AppData\Local\Programs\Python\Python310\lib\ast.py", line 81, in _convert_signed_num
    return _convert_num(node)
  File "C:\Users\idan5\AppData\Local\Programs\Python\Python310\lib\ast.py", line 72, in _convert_num
    _raise_malformed_node(node)
  File "C:\Users\idan5\AppData\Local\Programs\Python\Python310\lib\ast.py", line 69, in _raise_malformed_node
    raise ValueError(msg + f': {node!r}')
ValueError: malformed node or string: [{'intf': 'Ethernet0/1', 'ipaddr': 'unassigned', 'status': 'administratively down', 'proto': 'down'}, {'intf': 'Ethernet0/2', 'ipaddr': 'unassigned', 'status': 'administratively down', 'proto': 'down'}]

2022-08-22 23:19:26,986 -  nornir.core -     INFO -        run() - Running task 'another_show_command_test' with args {} on 1 hosts
2022-08-22 23:19:27,948 - nornir.core.task -    ERROR -      start() - Host 'R1': task 'another_show_command_test' failed with traceback:
Traceback (most recent call last):
  File "C:\Projects\zero_touch\api\.venv\lib\site-packages\nornir\core\task.py", line 99, in start
    r = self.task(self, **self.params)
  File "C:\Projects\zero_touch\api\zero_backend\zero_touch_api\views.py", line 26, in another_show_command_test
    print(ast.literal_eval(interfaces_result.result.lstrip("[").rstrip("]")))
AttributeError: 'list' object has no attribute 'lstrip'

2022-08-22 23:19:56,806 -  nornir.core -     INFO -        run() - Running task 'another_show_command_test' with args {} on 1 hosts
2022-08-22 23:22:14,865 -  nornir.core -     INFO -        run() - Running task 'another_show_command_test' with args {} on 1 hosts
2022-08-22 23:22:48,512 -  nornir.core -     INFO -        run() - Running task 'another_show_command_test' with args {} on 1 hosts
2022-08-23 20:52:32,032 -  nornir.core -     INFO -        run() - Running task 'another_show_command_test' with args {} on 1 hosts
2022-08-23 20:52:45,450 -  nornir.core -     INFO -        run() - Running task 'another_show_command_test' with args {} on 1 hosts
2022-08-23 20:52:49,897 -  nornir.core -     INFO -        run() - Running task 'another_show_command_test' with args {} on 1 hosts
2022-08-23 20:57:28,976 -  nornir.core -     INFO -        run() - Running task 'another_show_command_test' with args {} on 1 hosts
2022-08-23 21:44:44,811 -  nornir.core -     INFO -        run() - Running task 'another_show_command_test' with args {} on 1 hosts
2022-08-23 21:46:59,002 -  nornir.core -     INFO -        run() - Running task 'another_show_command_test' with args {} on 1 hosts
2022-08-23 21:47:29,770 -  nornir.core -     INFO -        run() - Running task 'another_show_command_test' with args {} on 1 hosts
2022-08-23 21:47:55,439 -  nornir.core -     INFO -        run() - Running task 'another_show_command_test' with args {} on 1 hosts
2022-08-23 21:50:41,661 -  nornir.core -     INFO -        run() - Running task 'another_show_command_test' with args {} on 1 hosts
2022-08-23 21:51:06,781 -  nornir.core -     INFO -        run() - Running task 'another_show_command_test' with args {} on 1 hosts
2022-08-23 21:55:33,352 -  nornir.core -     INFO -        run() - Running task 'another_show_command_test' with args {} on 1 hosts
2022-08-23 21:56:50,843 -  nornir.core -     INFO -        run() - Running task 'another_show_command_test' with args {} on 1 hosts
2022-08-23 21:57:17,809 -  nornir.core -     INFO -        run() - Running task 'another_show_command_test' with args {} on 1 hosts
2022-08-23 22:12:40,109 -  nornir.core -     INFO -        run() - Running task 'another_show_command_test' with args {} on 1 hosts
2022-08-23 22:12:55,145 -  nornir.core -     INFO -        run() - Running task 'another_show_command_test' with args {} on 1 hosts
2022-08-23 22:13:59,032 -  nornir.core -     INFO -        run() - Running task 'another_show_command_test' with args {} on 1 hosts
2022-08-23 22:14:51,805 -  nornir.core -     INFO -        run() - Running task 'another_show_command_test' with args {} on 1 hosts
2022-08-23 22:16:00,084 -  nornir.core -     INFO -        run() - Running task 'another_show_command_test' with args {} on 1 hosts
2022-08-23 22:18:07,448 -  nornir.core -     INFO -        run() - Running task 'another_show_command_test' with args {} on 1 hosts
2022-08-23 22:18:34,385 -  nornir.core -     INFO -        run() - Running task 'another_show_command_test' with args {} on 1 hosts
2022-08-23 22:18:44,175 -  nornir.core -     INFO -        run() - Running task 'another_show_command_test' with args {} on 1 hosts
2022-08-23 22:20:50,039 -  nornir.core -     INFO -        run() - Running task 'another_show_command_test' with args {} on 1 hosts
2022-08-23 22:21:36,394 -  nornir.core -     INFO -        run() - Running task 'another_show_command_test' with args {} on 1 hosts
2022-08-23 22:22:01,818 -  nornir.core -     INFO -        run() - Running task 'another_show_command_test' with args {} on 1 hosts
2022-08-23 22:23:29,412 -  nornir.core -     INFO -        run() - Running task 'another_show_command_test' with args {} on 1 hosts
2022-08-23 22:24:10,599 -  nornir.core -     INFO -        run() - Running task 'another_show_command_test' with args {} on 1 hosts
2022-08-23 22:25:20,871 -  nornir.core -     INFO -        run() - Running task 'another_show_command_test' with args {} on 1 hosts
2022-08-23 22:25:26,547 -  nornir.core -     INFO -        run() - Running task 'another_show_command_test' with args {} on 1 hosts
2022-08-23 22:25:48,767 -  nornir.core -     INFO -        run() - Running task 'another_show_command_test' with args {} on 1 hosts
2022-08-23 22:26:30,934 -  nornir.core -     INFO -        run() - Running task 'another_show_command_test' with args {} on 1 hosts
2022-08-23 22:26:32,035 -  nornir.core -     INFO -        run() - Running task 'another_show_command_test' with args {} on 1 hosts
2022-08-23 22:27:37,883 -  nornir.core -     INFO -        run() - Running task 'another_show_command_test' with args {} on 1 hosts
2022-08-23 22:28:24,977 -  nornir.core -     INFO -        run() - Running task 'another_show_command_test' with args {} on 1 hosts
2022-08-23 22:30:06,112 -  nornir.core -     INFO -        run() - Running task 'another_show_command_test' with args {} on 1 hosts
2022-08-23 22:30:34,417 -  nornir.core -     INFO -        run() - Running task 'another_show_command_test' with args {} on 1 hosts
2022-08-23 22:35:26,219 -  nornir.core -     INFO -        run() - Running task 'another_show_command_test' with args {} on 1 hosts
2022-08-23 22:35:35,669 -  nornir.core -     INFO -        run() - Running task 'another_show_command_test' with args {} on 1 hosts
2022-08-23 22:35:44,603 -  nornir.core -     INFO -        run() - Running task 'another_show_command_test' with args {} on 1 hosts
2022-08-23 22:36:30,848 -  nornir.core -     INFO -        run() - Running task 'another_show_command_test' with args {} on 1 hosts
2022-08-23 22:36:58,952 -  nornir.core -     INFO -        run() - Running task 'another_show_command_test' with args {} on 1 hosts
2022-08-23 22:43:12,103 -  nornir.core -     INFO -        run() - Running task 'another_show_command_test' with args {} on 1 hosts
2022-09-20 09:38:51,283 -  nornir.core -     INFO -        run() - Running task 'another_show_command_test' with args {} on 1 hosts
2022-09-20 09:39:01,700 - nornir.core.task -    ERROR -      start() - Host 'R1': task 'netmiko_send_command' failed with traceback:
Traceback (most recent call last):
  File "C:\Projects\zero_touch\api\.venv\lib\site-packages\netmiko\base_connection.py", line 1046, in establish_connection
    self.remote_conn_pre.connect(**ssh_connect_params)
  File "C:\Projects\zero_touch\api\.venv\lib\site-packages\paramiko\client.py", line 349, in connect
    retry_on_signal(lambda: sock.connect(addr))
  File "C:\Projects\zero_touch\api\.venv\lib\site-packages\paramiko\util.py", line 279, in retry_on_signal
    return function()
  File "C:\Projects\zero_touch\api\.venv\lib\site-packages\paramiko\client.py", line 349, in <lambda>
    retry_on_signal(lambda: sock.connect(addr))
TimeoutError: timed out

During handling of the above exception, another exception occurred:

Traceback (most recent call last):
  File "C:\Projects\zero_touch\api\.venv\lib\site-packages\nornir\core\task.py", line 99, in start
    r = self.task(self, **self.params)
  File "C:\Projects\zero_touch\api\.venv\lib\site-packages\nornir_netmiko\tasks\netmiko_send_command.py", line 26, in netmiko_send_command
    net_connect = task.host.get_connection(CONNECTION_NAME, task.nornir.config)
  File "C:\Projects\zero_touch\api\.venv\lib\site-packages\nornir\core\inventory.py", line 494, in get_connection
    self.open_connection(
  File "C:\Projects\zero_touch\api\.venv\lib\site-packages\nornir\core\inventory.py", line 546, in open_connection
    conn_obj.open(
  File "C:\Projects\zero_touch\api\.venv\lib\site-packages\nornir_netmiko\connections\netmiko.py", line 59, in open
    connection = ConnectHandler(**parameters)
  File "C:\Projects\zero_touch\api\.venv\lib\site-packages\netmiko\ssh_dispatcher.py", line 365, in ConnectHandler
    return ConnectionClass(*args, **kwargs)
  File "C:\Projects\zero_touch\api\.venv\lib\site-packages\netmiko\base_connection.py", line 439, in __init__
    self._open()
  File "C:\Projects\zero_touch\api\.venv\lib\site-packages\netmiko\base_connection.py", line 444, in _open
    self.establish_connection()
  File "C:\Projects\zero_touch\api\.venv\lib\site-packages\netmiko\base_connection.py", line 1068, in establish_connection
    raise NetmikoTimeoutException(msg)
netmiko.exceptions.NetmikoTimeoutException: TCP connection to device failed.

Common causes of this problem are:
1. Incorrect hostname or IP address.
2. Wrong TCP port.
3. Intermediate firewall blocking access.

Device settings: cisco_ios 192.168.19.101:22



2022-09-20 09:39:01,701 - nornir.core.task -    ERROR -      start() - Host 'R1': task 'another_show_command_test' failed with traceback:
Traceback (most recent call last):
  File "C:\Projects\zero_touch\api\.venv\lib\site-packages\nornir\core\task.py", line 99, in start
    r = self.task(self, **self.params)
  File "C:\Projects\zero_touch\api\zero_backend\zero_touch_api\views.py", line 21, in another_show_command_test
    interfaces_result = task.run(
  File "C:\Projects\zero_touch\api\.venv\lib\site-packages\nornir\core\task.py", line 174, in run
    raise NornirSubTaskError(task=run_task, result=r)
nornir.core.exceptions.NornirSubTaskError: Subtask: netmiko_send_command (failed)


2022-09-20 13:31:09,789 -  nornir.core -     INFO -        run() - Running task 'another_show_command_test' with args {} on 1 hosts
2022-09-20 13:31:55,086 -  nornir.core -     INFO -        run() - Running task 'another_show_command_test' with args {} on 1 hosts
2022-09-20 13:32:10,934 -  nornir.core -     INFO -        run() - Running task 'another_show_command_test' with args {} on 1 hosts
2022-09-20 13:32:58,945 -  nornir.core -     INFO -        run() - Running task 'another_show_command_test' with args {} on 1 hosts
2022-09-20 13:34:26,661 -  nornir.core -     INFO -        run() - Running task 'another_show_command_test' with args {} on 1 hosts
2022-09-20 13:34:36,704 - nornir.core.task -    ERROR -      start() - Host 'R1': task 'netmiko_send_command' failed with traceback:
Traceback (most recent call last):
  File "C:\Projects\zero_touch\api\.venv\lib\site-packages\netmiko\base_connection.py", line 1046, in establish_connection
    self.remote_conn_pre.connect(**ssh_connect_params)
  File "C:\Projects\zero_touch\api\.venv\lib\site-packages\paramiko\client.py", line 349, in connect
    retry_on_signal(lambda: sock.connect(addr))
  File "C:\Projects\zero_touch\api\.venv\lib\site-packages\paramiko\util.py", line 279, in retry_on_signal
    return function()
  File "C:\Projects\zero_touch\api\.venv\lib\site-packages\paramiko\client.py", line 349, in <lambda>
    retry_on_signal(lambda: sock.connect(addr))
TimeoutError: timed out

During handling of the above exception, another exception occurred:

Traceback (most recent call last):
  File "C:\Projects\zero_touch\api\.venv\lib\site-packages\nornir\core\task.py", line 99, in start
    r = self.task(self, **self.params)
  File "C:\Projects\zero_touch\api\.venv\lib\site-packages\nornir_netmiko\tasks\netmiko_send_command.py", line 26, in netmiko_send_command
    net_connect = task.host.get_connection(CONNECTION_NAME, task.nornir.config)
  File "C:\Projects\zero_touch\api\.venv\lib\site-packages\nornir\core\inventory.py", line 494, in get_connection
    self.open_connection(
  File "C:\Projects\zero_touch\api\.venv\lib\site-packages\nornir\core\inventory.py", line 546, in open_connection
    conn_obj.open(
  File "C:\Projects\zero_touch\api\.venv\lib\site-packages\nornir_netmiko\connections\netmiko.py", line 59, in open
    connection = ConnectHandler(**parameters)
  File "C:\Projects\zero_touch\api\.venv\lib\site-packages\netmiko\ssh_dispatcher.py", line 365, in ConnectHandler
    return ConnectionClass(*args, **kwargs)
  File "C:\Projects\zero_touch\api\.venv\lib\site-packages\netmiko\base_connection.py", line 439, in __init__
    self._open()
  File "C:\Projects\zero_touch\api\.venv\lib\site-packages\netmiko\base_connection.py", line 444, in _open
    self.establish_connection()
  File "C:\Projects\zero_touch\api\.venv\lib\site-packages\netmiko\base_connection.py", line 1068, in establish_connection
    raise NetmikoTimeoutException(msg)
netmiko.exceptions.NetmikoTimeoutException: TCP connection to device failed.

Common causes of this problem are:
1. Incorrect hostname or IP address.
2. Wrong TCP port.
3. Intermediate firewall blocking access.

Device settings: cisco_ios 192.168.19.101:22



2022-09-20 13:34:36,705 - nornir.core.task -    ERROR -      start() - Host 'R1': task 'another_show_command_test' failed with traceback:
Traceback (most recent call last):
  File "C:\Projects\zero_touch\api\.venv\lib\site-packages\nornir\core\task.py", line 99, in start
    r = self.task(self, **self.params)
  File "C:\Projects\zero_touch\api\zero_backend\zero_touch_api\views.py", line 21, in another_show_command_test
    interfaces_result = task.run(
  File "C:\Projects\zero_touch\api\.venv\lib\site-packages\nornir\core\task.py", line 174, in run
    raise NornirSubTaskError(task=run_task, result=r)
nornir.core.exceptions.NornirSubTaskError: Subtask: netmiko_send_command (failed)


2022-09-20 13:35:03,356 -  nornir.core -     INFO -        run() - Running task 'another_show_command_test' with args {} on 1 hosts
2022-09-20 13:36:11,330 -  nornir.core -     INFO -        run() - Running task 'another_show_command_test' with args {} on 1 hosts
                                                                                                                                     2022-11-29 12:01:15,097 -  nornir.core -     INFO -        run() - Running task 'another_show_command_test' with args {} on 1 hosts
2022-11-29 12:01:18,212 - nornir.core.task -    ERROR -      start() - Host 'R1': task 'netmiko_send_command' failed with traceback:
Traceback (most recent call last):
  File "/home/idansimantov/projects/zero_touch/api/.venv/lib/python3.10/site-packages/netmiko/base_connection.py", line 1046, in establish_connection
    self.remote_conn_pre.connect(**ssh_connect_params)
  File "/home/idansimantov/projects/zero_touch/api/.venv/lib/python3.10/site-packages/paramiko/client.py", line 381, in connect
    raise NoValidConnectionsError(errors)
paramiko.ssh_exception.NoValidConnectionsError: [Errno None] Unable to connect to port 22 on 192.168.19.101

During handling of the above exception, another exception occurred:

Traceback (most recent call last):
  File "/home/idansimantov/projects/zero_touch/api/.venv/lib/python3.10/site-packages/nornir/core/task.py", line 99, in start
    r = self.task(self, **self.params)
  File "/home/idansimantov/projects/zero_touch/api/.venv/lib/python3.10/site-packages/nornir_netmiko/tasks/netmiko_send_command.py", line 26, in netmiko_send_command
    net_connect = task.host.get_connection(CONNECTION_NAME, task.nornir.config)
  File "/home/idansimantov/projects/zero_touch/api/.venv/lib/python3.10/site-packages/nornir/core/inventory.py", line 494, in get_connection
    self.open_connection(
  File "/home/idansimantov/projects/zero_touch/api/.venv/lib/python3.10/site-packages/nornir/core/inventory.py", line 546, in open_connection
    conn_obj.open(
  File "/home/idansimantov/projects/zero_touch/api/.venv/lib/python3.10/site-packages/nornir_netmiko/connections/netmiko.py", line 59, in open
    connection = ConnectHandler(**parameters)
  File "/home/idansimantov/projects/zero_touch/api/.venv/lib/python3.10/site-packages/netmiko/ssh_dispatcher.py", line 365, in ConnectHandler
    return ConnectionClass(*args, **kwargs)
  File "/home/idansimantov/projects/zero_touch/api/.venv/lib/python3.10/site-packages/netmiko/base_connection.py", line 439, in __init__
    self._open()
  File "/home/idansimantov/projects/zero_touch/api/.venv/lib/python3.10/site-packages/netmiko/base_connection.py", line 444, in _open
    self.establish_connection()
  File "/home/idansimantov/projects/zero_touch/api/.venv/lib/python3.10/site-packages/netmiko/base_connection.py", line 1068, in establish_connection
    raise NetmikoTimeoutException(msg)
netmiko.exceptions.NetmikoTimeoutException: TCP connection to device failed.

Common causes of this problem are:
1. Incorrect hostname or IP address.
2. Wrong TCP port.
3. Intermediate firewall blocking access.

Device settings: cisco_ios 192.168.19.101:22



2022-11-29 12:01:18,213 - nornir.core.task -    ERROR -      start() - Host 'R1': task 'another_show_command_test' failed with traceback:
Traceback (most recent call last):
  File "/home/idansimantov/projects/zero_touch/api/.venv/lib/python3.10/site-packages/nornir/core/task.py", line 99, in start
    r = self.task(self, **self.params)
  File "/home/idansimantov/projects/zero_touch/api/zero_backend/zero_touch_api/views.py", line 77, in another_show_command_test
    interfaces_result = task.run(
  File "/home/idansimantov/projects/zero_touch/api/.venv/lib/python3.10/site-packages/nornir/core/task.py", line 174, in run
    raise NornirSubTaskError(task=run_task, result=r)
nornir.core.exceptions.NornirSubTaskError: Subtask: netmiko_send_command (failed)


2022-11-29 12:02:44,713 -  nornir.core -     INFO -        run() - Running task 'another_show_command_test' with args {} on 1 hosts
2022-11-29 12:02:54,781 - nornir.core.task -    ERROR -      start() - Host 'R1': task 'netmiko_send_command' failed with traceback:
Traceback (most recent call last):
  File "/home/idansimantov/projects/zero_touch/api/.venv/lib/python3.10/site-packages/netmiko/base_connection.py", line 1046, in establish_connection
    self.remote_conn_pre.connect(**ssh_connect_params)
  File "/home/idansimantov/projects/zero_touch/api/.venv/lib/python3.10/site-packages/paramiko/client.py", line 358, in connect
    retry_on_signal(lambda: sock.connect(addr))
  File "/home/idansimantov/projects/zero_touch/api/.venv/lib/python3.10/site-packages/paramiko/util.py", line 279, in retry_on_signal
    return function()
  File "/home/idansimantov/projects/zero_touch/api/.venv/lib/python3.10/site-packages/paramiko/client.py", line 358, in <lambda>
    retry_on_signal(lambda: sock.connect(addr))
TimeoutError: timed out

During handling of the above exception, another exception occurred:

Traceback (most recent call last):
  File "/home/idansimantov/projects/zero_touch/api/.venv/lib/python3.10/site-packages/nornir/core/task.py", line 99, in start
    r = self.task(self, **self.params)
  File "/home/idansimantov/projects/zero_touch/api/.venv/lib/python3.10/site-packages/nornir_netmiko/tasks/netmiko_send_command.py", line 26, in netmiko_send_command
    net_connect = task.host.get_connection(CONNECTION_NAME, task.nornir.config)
  File "/home/idansimantov/projects/zero_touch/api/.venv/lib/python3.10/site-packages/nornir/core/inventory.py", line 494, in get_connection
    self.open_connection(
  File "/home/idansimantov/projects/zero_touch/api/.venv/lib/python3.10/site-packages/nornir/core/inventory.py", line 546, in open_connection
    conn_obj.open(
  File "/home/idansimantov/projects/zero_touch/api/.venv/lib/python3.10/site-packages/nornir_netmiko/connections/netmiko.py", line 59, in open
    connection = ConnectHandler(**parameters)
  File "/home/idansimantov/projects/zero_touch/api/.venv/lib/python3.10/site-packages/netmiko/ssh_dispatcher.py", line 365, in ConnectHandler
    return ConnectionClass(*args, **kwargs)
  File "/home/idansimantov/projects/zero_touch/api/.venv/lib/python3.10/site-packages/netmiko/base_connection.py", line 439, in __init__
    self._open()
  File "/home/idansimantov/projects/zero_touch/api/.venv/lib/python3.10/site-packages/netmiko/base_connection.py", line 444, in _open
    self.establish_connection()
  File "/home/idansimantov/projects/zero_touch/api/.venv/lib/python3.10/site-packages/netmiko/base_connection.py", line 1068, in establish_connection
    raise NetmikoTimeoutException(msg)
netmiko.exceptions.NetmikoTimeoutException: TCP connection to device failed.

Common causes of this problem are:
1. Incorrect hostname or IP address.
2. Wrong TCP port.
3. Intermediate firewall blocking access.

Device settings: cisco_ios 192.168.19.101:22



2022-11-29 12:02:54,783 - nornir.core.task -    ERROR -      start() - Host 'R1': task 'another_show_command_test' failed with traceback:
Traceback (most recent call last):
  File "/home/idansimantov/projects/zero_touch/api/.venv/lib/python3.10/site-packages/nornir/core/task.py", line 99, in start
    r = self.task(self, **self.params)
  File "/home/idansimantov/projects/zero_touch/api/zero_backend/zero_touch_api/views.py", line 77, in another_show_command_test
    interfaces_result = task.run(
  File "/home/idansimantov/projects/zero_touch/api/.venv/lib/python3.10/site-packages/nornir/core/task.py", line 174, in run
    raise NornirSubTaskError(task=run_task, result=r)
nornir.core.exceptions.NornirSubTaskError: Subtask: netmiko_send_command (failed)


2022-11-29 12:06:45,442 -  nornir.core -     INFO -        run() - Running task 'another_show_command_test' with args {} on 1 hosts
2022-11-29 12:30:42,257 -  nornir.core -     INFO -        run() - Running task 'another_show_command_test' with args {} on 1 hosts
2022-11-29 12:31:03,803 -  nornir.core -     INFO -        run() - Running task 'another_show_command_test' with args {} on 1 hosts
2022-11-29 12:31:30,192 -  nornir.core -     INFO -        run() - Running task 'another_show_command_test' with args {} on 1 hosts
2022-11-29 12:31:31,282 - nornir.core.task -    ERROR -      start() - Host 'R1': task 'another_show_command_test' failed with traceback:
Traceback (most recent call last):
  File "/home/idansimantov/projects/zero_touch/api/.venv/lib/python3.10/site-packages/nornir/core/task.py", line 99, in start
    r = self.task(self, **self.params)
  File "/home/idansimantov/projects/zero_touch/api/zero_backend/zero_touch_api/views.py", line 82, in another_show_command_test
    task.host["facts"] = interfaces_result.textfsm_parse_output()
  File "/home/idansimantov/projects/zero_touch/api/.venv/lib/python3.10/site-packages/nornir/core/task.py", line 255, in __getattr__
    return getattr(self[0], name)
AttributeError: 'Result' object has no attribute 'textfsm_parse_output'

2022-11-29 12:32:28,273 -  nornir.core -     INFO -        run() - Running task 'another_show_command_test' with args {} on 1 hosts
2022-11-29 12:32:29,421 - nornir.core.task -    ERROR -      start() - Host 'R1': task 'another_show_command_test' failed with traceback:
Traceback (most recent call last):
  File "/home/idansimantov/projects/zero_touch/api/.venv/lib/python3.10/site-packages/nornir/core/task.py", line 99, in start
    r = self.task(self, **self.params)
  File "/home/idansimantov/projects/zero_touch/api/zero_backend/zero_touch_api/views.py", line 82, in another_show_command_test
    task.host["facts"] = interfaces_result.textfsm_parse_output()
  File "/home/idansimantov/projects/zero_touch/api/.venv/lib/python3.10/site-packages/nornir/core/task.py", line 255, in __getattr__
    return getattr(self[0], name)
AttributeError: 'Result' object has no attribute 'textfsm_parse_output'

2022-11-29 12:34:28,858 -  nornir.core -     INFO -        run() - Running task 'another_show_command_test' with args {} on 1 hosts
2022-11-29 12:34:30,060 - nornir.core.task -    ERROR -      start() - Host 'R1': task 'another_show_command_test' failed with traceback:
Traceback (most recent call last):
  File "/home/idansimantov/projects/zero_touch/api/.venv/lib/python3.10/site-packages/nornir/core/task.py", line 99, in start
    r = self.task(self, **self.params)
  File "/home/idansimantov/projects/zero_touch/api/zero_backend/zero_touch_api/views.py", line 82, in another_show_command_test
    task.host["facts"] = interfaces_result.textfsm_parse_output()
  File "/home/idansimantov/projects/zero_touch/api/.venv/lib/python3.10/site-packages/nornir/core/task.py", line 255, in __getattr__
    return getattr(self[0], name)
AttributeError: 'Result' object has no attribute 'textfsm_parse_output'

2022-11-29 12:35:43,812 -  nornir.core -     INFO -        run() - Running task 'another_show_command_test' with args {} on 1 hosts
2022-11-29 12:35:44,985 - nornir.core.task -    ERROR -      start() - Host 'R1': task 'another_show_command_test' failed with traceback:
Traceback (most recent call last):
  File "/home/idansimantov/projects/zero_touch/api/.venv/lib/python3.10/site-packages/nornir/core/task.py", line 99, in start
    r = self.task(self, **self.params)
  File "/home/idansimantov/projects/zero_touch/api/zero_backend/zero_touch_api/views.py", line 82, in another_show_command_test
    task.host["facts"] = interfaces_result.genie_parse_output()
  File "/home/idansimantov/projects/zero_touch/api/.venv/lib/python3.10/site-packages/nornir/core/task.py", line 255, in __getattr__
    return getattr(self[0], name)
AttributeError: 'Result' object has no attribute 'genie_parse_output'

2022-11-29 12:37:18,057 -  nornir.core -     INFO -        run() - Running task 'another_show_command_test' with args {} on 1 hosts
2022-11-29 12:37:19,292 - nornir.core.task -    ERROR -      start() - Host 'R1': task 'netmiko_send_command' failed with traceback:
Traceback (most recent call last):
  File "/home/idansimantov/projects/zero_touch/api/.venv/lib/python3.10/site-packages/nornir/core/task.py", line 99, in start
    r = self.task(self, **self.params)
  File "/home/idansimantov/projects/zero_touch/api/.venv/lib/python3.10/site-packages/nornir_netmiko/tasks/netmiko_send_command.py", line 32, in netmiko_send_command
    result = net_connect.send_command(command_string, **kwargs)
  File "/home/idansimantov/projects/zero_touch/api/.venv/lib/python3.10/site-packages/netmiko/utilities.py", line 592, in wrapper_decorator
    return func(self, *args, **kwargs)
  File "/home/idansimantov/projects/zero_touch/api/.venv/lib/python3.10/site-packages/netmiko/base_connection.py", line 1729, in send_command
    return_val = structured_data_converter(
  File "/home/idansimantov/projects/zero_touch/api/.venv/lib/python3.10/site-packages/netmiko/utilities.py", line 577, in structured_data_converter
    structured_output_genie = get_structured_data_genie(
  File "/home/idansimantov/projects/zero_touch/api/.venv/lib/python3.10/site-packages/netmiko/utilities.py", line 500, in get_structured_data_genie
    raise ValueError(msg)
ValueError: 
Genie and PyATS are not installed. Please PIP install both Genie and PyATS:
pip install genie
pip install pyats


2022-11-29 12:37:19,293 - nornir.core.task -    ERROR -      start() - Host 'R1': task 'another_show_command_test' failed with traceback:
Traceback (most recent call last):
  File "/home/idansimantov/projects/zero_touch/api/.venv/lib/python3.10/site-packages/nornir/core/task.py", line 99, in start
    r = self.task(self, **self.params)
  File "/home/idansimantov/projects/zero_touch/api/zero_backend/zero_touch_api/views.py", line 77, in another_show_command_test
    interfaces_result = task.run(
  File "/home/idansimantov/projects/zero_touch/api/.venv/lib/python3.10/site-packages/nornir/core/task.py", line 174, in run
    raise NornirSubTaskError(task=run_task, result=r)
nornir.core.exceptions.NornirSubTaskError: Subtask: netmiko_send_command (failed)


2022-11-29 15:01:57,976 -  nornir.core -     INFO -        run() - Running task 'another_show_command_test' with args {} on 1 hosts
2022-11-29 15:01:58,820 - nornir.core.task -    ERROR -      start() - Host 'R1': task 'netmiko_send_command' failed with traceback:
Traceback (most recent call last):
  File "/home/idansimantov/projects/zero_touch/api/.venv/lib/python3.10/site-packages/nornir/core/task.py", line 99, in start
    r = self.task(self, **self.params)
  File "/home/idansimantov/projects/zero_touch/api/.venv/lib/python3.10/site-packages/nornir_netmiko/tasks/netmiko_send_command.py", line 32, in netmiko_send_command
    result = net_connect.send_command(command_string, **kwargs)
  File "/home/idansimantov/projects/zero_touch/api/.venv/lib/python3.10/site-packages/netmiko/utilities.py", line 592, in wrapper_decorator
    return func(self, *args, **kwargs)
  File "/home/idansimantov/projects/zero_touch/api/.venv/lib/python3.10/site-packages/netmiko/base_connection.py", line 1729, in send_command
    return_val = structured_data_converter(
  File "/home/idansimantov/projects/zero_touch/api/.venv/lib/python3.10/site-packages/netmiko/utilities.py", line 577, in structured_data_converter
    structured_output_genie = get_structured_data_genie(
  File "/home/idansimantov/projects/zero_touch/api/.venv/lib/python3.10/site-packages/netmiko/utilities.py", line 500, in get_structured_data_genie
    raise ValueError(msg)
ValueError: 
Genie and PyATS are not installed. Please PIP install both Genie and PyATS:
pip install genie
pip install pyats


2022-11-29 15:01:58,821 - nornir.core.task -    ERROR -      start() - Host 'R1': task 'another_show_command_test' failed with traceback:
Traceback (most recent call last):
  File "/home/idansimantov/projects/zero_touch/api/.venv/lib/python3.10/site-packages/nornir/core/task.py", line 99, in start
    r = self.task(self, **self.params)
  File "/home/idansimantov/projects/zero_touch/api/zero_backend/zero_touch_api/views.py", line 77, in another_show_command_test
    interfaces_result = task.run(
  File "/home/idansimantov/projects/zero_touch/api/.venv/lib/python3.10/site-packages/nornir/core/task.py", line 174, in run
    raise NornirSubTaskError(task=run_task, result=r)
nornir.core.exceptions.NornirSubTaskError: Subtask: netmiko_send_command (failed)


2022-11-29 15:10:11,070 -  nornir.core -     INFO -        run() - Running task 'another_show_command_test' with args {} on 1 hosts
2022-11-29 15:10:11,934 - nornir.core.task -    ERROR -      start() - Host 'R1': task 'netmiko_send_command' failed with traceback:
Traceback (most recent call last):
  File "/home/idansimantov/projects/zero_touch/api/.venv/lib/python3.10/site-packages/nornir/core/task.py", line 99, in start
    r = self.task(self, **self.params)
  File "/home/idansimantov/projects/zero_touch/api/.venv/lib/python3.10/site-packages/nornir_netmiko/tasks/netmiko_send_command.py", line 32, in netmiko_send_command
    result = net_connect.send_command(command_string, **kwargs)
  File "/home/idansimantov/projects/zero_touch/api/.venv/lib/python3.10/site-packages/netmiko/utilities.py", line 592, in wrapper_decorator
    return func(self, *args, **kwargs)
  File "/home/idansimantov/projects/zero_touch/api/.venv/lib/python3.10/site-packages/netmiko/base_connection.py", line 1729, in send_command
    return_val = structured_data_converter(
  File "/home/idansimantov/projects/zero_touch/api/.venv/lib/python3.10/site-packages/netmiko/utilities.py", line 577, in structured_data_converter
    structured_output_genie = get_structured_data_genie(
  File "/home/idansimantov/projects/zero_touch/api/.venv/lib/python3.10/site-packages/netmiko/utilities.py", line 500, in get_structured_data_genie
    raise ValueError(msg)
ValueError: 
Genie and PyATS are not installed. Please PIP install both Genie and PyATS:
pip install genie
pip install pyats


2022-11-29 15:10:11,935 - nornir.core.task -    ERROR -      start() - Host 'R1': task 'another_show_command_test' failed with traceback:
Traceback (most recent call last):
  File "/home/idansimantov/projects/zero_touch/api/.venv/lib/python3.10/site-packages/nornir/core/task.py", line 99, in start
    r = self.task(self, **self.params)
  File "/home/idansimantov/projects/zero_touch/api/zero_backend/zero_touch_api/views.py", line 77, in another_show_command_test
    interfaces_result = task.run(
  File "/home/idansimantov/projects/zero_touch/api/.venv/lib/python3.10/site-packages/nornir/core/task.py", line 174, in run
    raise NornirSubTaskError(task=run_task, result=r)
nornir.core.exceptions.NornirSubTaskError: Subtask: netmiko_send_command (failed)


2022-11-29 15:26:18,767 -  nornir.core -     INFO -        run() - Running task 'another_show_command_test' with args {} on 1 hosts
2022-11-29 15:31:15,093 -  nornir.core -     INFO -        run() - Running task 'another_show_command_test' with args {} on 1 hosts
2022-11-29 18:32:17,064 -  nornir.core -     INFO -        run() - Running task 'another_show_command_test' with args {} on 1 hosts
2022-11-29 18:32:18,131 - nornir.core.task -    ERROR -      start() - Host 'R1': task 'netmiko_send_command' failed with traceback:
Traceback (most recent call last):
  File "/home/idansimantov/projects/zero_touch/api/.venv/lib/python3.10/site-packages/nornir/core/task.py", line 99, in start
    r = self.task(self, **self.params)
  File "/home/idansimantov/projects/zero_touch/api/.venv/lib/python3.10/site-packages/nornir_netmiko/tasks/netmiko_send_command.py", line 32, in netmiko_send_command
    result = net_connect.send_command(command_string, **kwargs)
  File "/home/idansimantov/projects/zero_touch/api/.venv/lib/python3.10/site-packages/netmiko/utilities.py", line 592, in wrapper_decorator
    return func(self, *args, **kwargs)
  File "/home/idansimantov/projects/zero_touch/api/.venv/lib/python3.10/site-packages/netmiko/base_connection.py", line 1729, in send_command
    return_val = structured_data_converter(
  File "/home/idansimantov/projects/zero_touch/api/.venv/lib/python3.10/site-packages/netmiko/utilities.py", line 577, in structured_data_converter
    structured_output_genie = get_structured_data_genie(
  File "/home/idansimantov/projects/zero_touch/api/.venv/lib/python3.10/site-packages/netmiko/utilities.py", line 500, in get_structured_data_genie
    raise ValueError(msg)
ValueError: 
Genie and PyATS are not installed. Please PIP install both Genie and PyATS:
pip install genie
pip install pyats


2022-11-29 18:32:18,132 - nornir.core.task -    ERROR -      start() - Host 'R1': task 'another_show_command_test' failed with traceback:
Traceback (most recent call last):
  File "/home/idansimantov/projects/zero_touch/api/.venv/lib/python3.10/site-packages/nornir/core/task.py", line 99, in start
    r = self.task(self, **self.params)
  File "/home/idansimantov/projects/zero_touch/api/zero_backend/zero_touch_api/views.py", line 77, in another_show_command_test
    interfaces_result = task.run(
  File "/home/idansimantov/projects/zero_touch/api/.venv/lib/python3.10/site-packages/nornir/core/task.py", line 174, in run
    raise NornirSubTaskError(task=run_task, result=r)
nornir.core.exceptions.NornirSubTaskError: Subtask: netmiko_send_command (failed)


2022-11-29 18:51:36,857 -  nornir.core -     INFO -        run() - Running task 'another_show_command_test' with args {} on 1 hosts
2022-11-29 18:53:03,883 -  nornir.core -     INFO -        run() - Running task 'another_show_command_test' with args {} on 1 hosts
2022-11-29 18:53:20,686 -  nornir.core -     INFO -        run() - Running task 'another_show_command_test' with args {} on 1 hosts
2022-11-29 19:13:45,948 -  nornir.core -     INFO -        run() - Running task 'another_show_command_test' with args {} on 1 hosts
2022-11-29 19:20:10,930 -  nornir.core -     INFO -        run() - Running task 'another_show_command_test' with args {} on 1 hosts
2022-11-29 19:51:15,262 -  nornir.core -     INFO -        run() - Running task 'another_show_command_test' with args {} on 1 hosts
2022-11-29 19:51:24,636 - nornir.core.task -    ERROR -      start() - Host 'R1': task 'another_show_command_test' failed with traceback:
Traceback (most recent call last):
  File "/home/idansimantov/projects/zero_touch/api/.venv/lib/python3.10/site-packages/nornir/core/task.py", line 99, in start
    r = self.task(self, **self.params)
  File "/home/idansimantov/projects/zero_touch/api/zero_backend/zero_touch_api/views.py", line 83, in another_show_command_test
    task.host["facts"] = json.loads(interfaces_result.result)
  File "/usr/lib/python3.10/json/__init__.py", line 346, in loads
    return _default_decoder.decode(s)
  File "/usr/lib/python3.10/json/decoder.py", line 337, in decode
    obj, end = self.raw_decode(s, idx=_w(s, 0).end())
  File "/usr/lib/python3.10/json/decoder.py", line 355, in raw_decode
    raise JSONDecodeError("Expecting value", s, err.value) from None
json.decoder.JSONDecodeError: Expecting value: line 1 column 1 (char 0)

2022-11-29 19:53:02,054 -  nornir.core -     INFO -        run() - Running task 'another_show_command_test' with args {} on 1 hosts
2022-11-29 19:57:03,976 -  nornir.core -     INFO -        run() - Running task 'another_show_command_test' with args {} on 1 hosts
2022-11-29 19:57:09,899 - nornir.core.task -    ERROR -      start() - Host 'R1': task 'another_show_command_test' failed with traceback:
Traceback (most recent call last):
  File "/home/idansimantov/projects/zero_touch/api/.venv/lib/python3.10/site-packages/nornir/core/task.py", line 99, in start
    r = self.task(self, **self.params)
  File "/home/idansimantov/projects/zero_touch/api/zero_backend/zero_touch_api/views.py", line 85, in another_show_command_test
    task.host["facts"] = get_json(interfaces_result.result)
TypeError: 'module' object is not callable

2022-11-29 20:02:05,523 -  nornir.core -     INFO -        run() - Running task 'another_show_command_test' with args {} on 1 hosts
2022-11-29 20:02:12,111 - nornir.core.task -    ERROR -      start() - Host 'R1': task 'another_show_command_test' failed with traceback:
Traceback (most recent call last):
  File "/home/idansimantov/projects/zero_touch/api/.venv/lib/python3.10/site-packages/nornir/core/task.py", line 99, in start
    r = self.task(self, **self.params)
  File "/home/idansimantov/projects/zero_touch/api/zero_backend/zero_touch_api/views.py", line 85, in another_show_command_test
    task.host["facts"] = get_parser(interfaces_result.result)
TypeError: get_parser() missing 1 required positional argument: 'device'

2022-11-29 20:03:58,849 -  nornir.core -     INFO -        run() - Running task 'another_show_command_test' with args {} on 1 hosts
2022-11-29 20:04:05,672 - nornir.core.task -    ERROR -      start() - Host 'R1': task 'another_show_command_test' failed with traceback:
Traceback (most recent call last):
  File "/home/idansimantov/projects/zero_touch/api/.venv/lib/python3.10/site-packages/nornir/core/task.py", line 99, in start
    r = self.task(self, **self.params)
  File "/home/idansimantov/projects/zero_touch/api/zero_backend/zero_touch_api/views.py", line 85, in another_show_command_test
    task.host["facts"] = format_output(interfaces_result.result)
  File "/home/idansimantov/projects/zero_touch/api/.venv/lib/python3.10/site-packages/genie/libs/parser/utils/common.py", line 119, in format_output
    for k, v in sorted(parser_data.items()):
AttributeError: 'str' object has no attribute 'items'

2022-11-29 20:08:54,761 -  nornir.core -     INFO -        run() - Running task 'another_show_command_test' with args {} on 1 hosts
2022-11-29 20:09:01,634 - nornir.core.task -    ERROR -      start() - Host 'R1': task 'another_show_command_test' failed with traceback:
Traceback (most recent call last):
  File "/home/idansimantov/projects/zero_touch/api/.venv/lib/python3.10/site-packages/nornir/core/task.py", line 99, in start
    r = self.task(self, **self.params)
  File "/home/idansimantov/projects/zero_touch/api/zero_backend/zero_touch_api/views.py", line 85, in another_show_command_test
    task.host["facts"] = get_parser(interfaces_result)
TypeError: get_parser() missing 1 required positional argument: 'device'

2022-11-29 20:15:39,697 -  nornir.core -     INFO -        run() - Running task 'another_show_command_test' with args {} on 1 hosts
2022-11-29 20:15:45,925 - nornir.core.task -    ERROR -      start() - Host 'R1': task 'another_show_command_test' failed with traceback:
Traceback (most recent call last):
  File "/home/idansimantov/projects/zero_touch/api/.venv/lib/python3.10/site-packages/nornir/core/task.py", line 99, in start
    r = self.task(self, **self.params)
  File "/home/idansimantov/projects/zero_touch/api/zero_backend/zero_touch_api/views.py", line 85, in another_show_command_test
    task.host["facts"] = format_output(interfaces_result.result)
  File "/home/idansimantov/projects/zero_touch/api/.venv/lib/python3.10/site-packages/genie/libs/parser/utils/common.py", line 119, in format_output
    for k, v in sorted(parser_data.items()):
AttributeError: 'str' object has no attribute 'items'

2022-11-29 20:16:13,308 -  nornir.core -     INFO -        run() - Running task 'another_show_command_test' with args {} on 1 hosts
2022-11-29 20:16:20,651 - nornir.core.task -    ERROR -      start() - Host 'R1': task 'another_show_command_test' failed with traceback:
Traceback (most recent call last):
  File "/home/idansimantov/projects/zero_touch/api/.venv/lib/python3.10/site-packages/nornir/core/task.py", line 99, in start
    r = self.task(self, **self.params)
  File "/home/idansimantov/projects/zero_touch/api/zero_backend/zero_touch_api/views.py", line 85, in another_show_command_test
    task.host["facts"] = format_output(interfaces_result)
  File "/home/idansimantov/projects/zero_touch/api/.venv/lib/python3.10/site-packages/genie/libs/parser/utils/common.py", line 119, in format_output
    for k, v in sorted(parser_data.items()):
  File "/home/idansimantov/projects/zero_touch/api/.venv/lib/python3.10/site-packages/nornir/core/task.py", line 255, in __getattr__
    return getattr(self[0], name)
AttributeError: 'Result' object has no attribute 'items'

2022-11-29 20:26:45,661 -  nornir.core -     INFO -        run() - Running task 'another_show_command_test' with args {} on 1 hosts
2022-11-29 20:30:42,209 -  nornir.core -     INFO -        run() - Running task 'another_show_command_test' with args {} on 1 hosts
2022-11-29 20:31:10,059 -  nornir.core -     INFO -        run() - Running task 'another_show_command_test' with args {} on 1 hosts
2022-11-29 20:31:45,466 -  nornir.core -     INFO -        run() - Running task 'another_show_command_test' with args {} on 1 hosts
2022-11-29 20:41:55,601 -  nornir.core -     INFO -        run() - Running task 'another_show_command_test' with args {} on 1 hosts
2022-11-29 20:42:08,757 -  nornir.core -     INFO -        run() - Running task 'another_show_command_test' with args {} on 1 hosts
2022-11-29 20:42:33,001 -  nornir.core -     INFO -        run() - Running task 'another_show_command_test' with args {} on 1 hosts
2022-11-29 20:43:05,569 -  nornir.core -     INFO -        run() - Running task 'another_show_command_test' with args {} on 1 hosts
2022-11-29 20:52:52,868 -  nornir.core -     INFO -        run() - Running task 'another_show_command_test' with args {} on 1 hosts
2022-11-29 20:52:59,629 - nornir.core.task -    ERROR -      start() - Host 'R1': task 'another_show_command_test' failed with traceback:
Traceback (most recent call last):
  File "/home/idansimantov/projects/zero_touch/api/.venv/lib/python3.10/site-packages/nornir/core/task.py", line 99, in start
    r = self.task(self, **self.params)
  File "/home/idansimantov/projects/zero_touch/api/zero_backend/zero_touch_api/views.py", line 86, in another_show_command_test
    task.host["facts"] = parsergen.oper_fill_tabular(
  File "src/genie/parsergen/_parsergen.py", line 802, in genie.parsergen._parsergen.oper_fill_tabular.__init__
  File "/home/idansimantov/projects/zero_touch/api/.venv/lib/python3.10/site-packages/nornir/core/task.py", line 255, in __getattr__
    return getattr(self[0], name)
AttributeError: 'Result' object has no attribute 'replace'

2022-11-30 20:10:03,931 -  nornir.core -     INFO -        run() - Running task 'another_show_command_test' with args {} on 1 hosts
2022-11-30 20:10:21,949 - nornir.core.task -    ERROR -      start() - Host 'R1': task 'another_show_command_test' failed with traceback:
Traceback (most recent call last):
  File "/home/idansimantov/projects/zero_touch/api/.venv/lib/python3.10/site-packages/nornir/core/task.py", line 99, in start
    r = self.task(self, **self.params)
  File "/home/idansimantov/projects/zero_touch/api/zero_backend/zero_touch_api/views.py", line 86, in another_show_command_test
    print(json.dumps(interfaces_result, indent=4, sort_keys=True))
  File "/usr/lib/python3.10/json/__init__.py", line 238, in dumps
    **kw).encode(obj)
  File "/usr/lib/python3.10/json/encoder.py", line 201, in encode
    chunks = list(chunks)
  File "/usr/lib/python3.10/json/encoder.py", line 429, in _iterencode
    yield from _iterencode_list(o, _current_indent_level)
  File "/usr/lib/python3.10/json/encoder.py", line 325, in _iterencode_list
    yield from chunks
  File "/usr/lib/python3.10/json/encoder.py", line 438, in _iterencode
    o = _default(o)
  File "/usr/lib/python3.10/json/encoder.py", line 179, in default
    raise TypeError(f'Object of type {o.__class__.__name__} '
TypeError: Object of type Result is not JSON serializable

2022-11-30 20:11:26,658 -  nornir.core -     INFO -        run() - Running task 'another_show_command_test' with args {} on 1 hosts
2022-11-30 20:26:28,783 -  nornir.core -     INFO -        run() - Running task 'another_show_command_test' with args {} on 1 hosts
2022-11-30 20:26:50,010 - nornir.core.task -    ERROR -      start() - Host 'R1': task 'another_show_command_test' failed with traceback:
Traceback (most recent call last):
  File "src/pyats/datastructures/listdict.py", line 95, in pyats.datastructures.listdict.ListDict.__init__
ValueError: too many values to unpack (expected 2)

During handling of the above exception, another exception occurred:

Traceback (most recent call last):
  File "/home/idansimantov/projects/zero_touch/api/.venv/lib/python3.10/site-packages/nornir/core/task.py", line 99, in start
    r = self.task(self, **self.params)
  File "/home/idansimantov/projects/zero_touch/api/zero_backend/zero_touch_api/views.py", line 89, in another_show_command_test
    print(Dq(interfaces_result.result))
  File "src/genie/utils/dq.py", line 22, in genie.utils.dq.Dq.__init__
  File "src/pyats/datastructures/listdict.py", line 97, in pyats.datastructures.listdict.ListDict.__init__
ValueError: ListDict only accepts a tuple of path/obj

2022-11-30 20:28:20,280 -  nornir.core -     INFO -        run() - Running task 'another_show_command_test' with args {} on 1 hosts
2022-11-30 20:28:40,091 - nornir.core.task -    ERROR -      start() - Host 'R1': task 'another_show_command_test' failed with traceback:
Traceback (most recent call last):
  File "/home/idansimantov/projects/zero_touch/api/.venv/lib/python3.10/site-packages/nornir/core/task.py", line 99, in start
    r = self.task(self, **self.params)
  File "/home/idansimantov/projects/zero_touch/api/zero_backend/zero_touch_api/views.py", line 89, in another_show_command_test
    print(QDict(interfaces_result.result))
ValueError: dictionary update sequence element #0 has length 1; 2 is required

2022-11-30 21:18:39,233 -  nornir.core -     INFO -        run() - Running task 'another_show_command_test' with args {} on 1 hosts
2022-11-30 21:18:59,002 - nornir.core.task -    ERROR -      start() - Host 'R1': task 'another_show_command_test' failed with traceback:
Traceback (most recent call last):
  File "/home/idansimantov/projects/zero_touch/api/.venv/lib/python3.10/site-packages/nornir/core/task.py", line 99, in start
    r = self.task(self, **self.params)
  File "/home/idansimantov/projects/zero_touch/api/zero_backend/zero_touch_api/views.py", line 89, in another_show_command_test
    print(get_json(interfaces_result.result))
TypeError: 'module' object is not callable

2022-12-01 07:40:55,085 -  nornir.core -     INFO -        run() - Running task 'another_show_command_test' with args {} on 1 hosts
2022-12-01 07:46:07,337 -  nornir.core -     INFO -        run() - Running task 'another_show_command_test' with args {} on 1 hosts
2022-12-01 07:46:14,581 - nornir.core.task -    ERROR -      start() - Host 'R1': task 'another_show_command_test' failed with traceback:
Traceback (most recent call last):
  File "/home/idansimantov/projects/zero_touch/api/.venv/lib/python3.10/site-packages/nornir/core/task.py", line 99, in start
    r = self.task(self, **self.params)
  File "/home/idansimantov/projects/zero_touch/api/zero_backend/zero_touch_api/views.py", line 90, in another_show_command_test
    print(json.loads(interfaces_result.result))
  File "/usr/lib/python3.10/json/__init__.py", line 346, in loads
    return _default_decoder.decode(s)
  File "/usr/lib/python3.10/json/decoder.py", line 337, in decode
    obj, end = self.raw_decode(s, idx=_w(s, 0).end())
  File "/usr/lib/python3.10/json/decoder.py", line 355, in raw_decode
    raise JSONDecodeError("Expecting value", s, err.value) from None
json.decoder.JSONDecodeError: Expecting value: line 1 column 1 (char 0)

2022-12-01 07:50:28,143 -  nornir.core -     INFO -        run() - Running task 'another_show_command_test' with args {} on 1 hosts
2022-12-01 07:50:34,706 - nornir.core.task -    ERROR -      start() - Host 'R1': task 'another_show_command_test' failed with traceback:
Traceback (most recent call last):
  File "/home/idansimantov/projects/zero_touch/api/.venv/lib/python3.10/site-packages/nornir/core/task.py", line 99, in start
    r = self.task(self, **self.params)
  File "/home/idansimantov/projects/zero_touch/api/zero_backend/zero_touch_api/views.py", line 90, in another_show_command_test
    print(json.dumps(interfaces_result.result.__dict__, sort_keys=False, indent=4))
AttributeError: 'str' object has no attribute '__dict__'

2022-12-01 07:51:04,517 -  nornir.core -     INFO -        run() - Running task 'another_show_command_test' with args {} on 1 hosts
2022-12-01 07:52:00,207 -  nornir.core -     INFO -        run() - Running task 'another_show_command_test' with args {} on 1 hosts
2022-12-01 07:59:56,736 -  nornir.core -     INFO -        run() - Running task 'another_show_command_test' with args {} on 1 hosts
2022-12-01 08:00:02,791 - nornir.core.task -    ERROR -      start() - Host 'R1': task 'another_show_command_test' failed with traceback:
Traceback (most recent call last):
  File "/home/idansimantov/projects/zero_touch/api/.venv/lib/python3.10/site-packages/nornir/core/task.py", line 99, in start
    r = self.task(self, **self.params)
  File "/home/idansimantov/projects/zero_touch/api/zero_backend/zero_touch_api/views.py", line 90, in another_show_command_test
    print(json.dumps(interfaces_result.result.keys(), sort_keys=False, indent=4))
AttributeError: 'str' object has no attribute 'keys'

2022-12-01 08:42:23,930 -  nornir.core -     INFO -        run() - Running task 'another_show_command_test' with args {} on 1 hosts
2022-12-01 08:42:59,137 -  nornir.core -     INFO -        run() - Running task 'another_show_command_test' with args {} on 1 hosts
2022-12-01 08:45:40,271 -  nornir.core -     INFO -        run() - Running task 'another_show_command_test' with args {} on 1 hosts
2022-12-01 08:51:08,822 -  nornir.core -     INFO -        run() - Running task 'another_show_command_test' with args {} on 1 hosts
2022-12-01 08:52:33,198 -  nornir.core -     INFO -        run() - Running task 'another_show_command_test' with args {} on 1 hosts
2022-12-01 08:52:40,388 - nornir.core.task -    ERROR -      start() - Host 'R1': task 'another_show_command_test' failed with traceback:
Traceback (most recent call last):
  File "/home/idansimantov/projects/zero_touch/api/.venv/lib/python3.10/site-packages/nornir/core/task.py", line 99, in start
    r = self.task(self, **self.params)
  File "/home/idansimantov/projects/zero_touch/api/zero_backend/zero_touch_api/views.py", line 90, in another_show_command_test
    print(json.loads(interfaces_result.result.__dict__, sort_keys=False, indent=4))
  File "/usr/lib/python3.10/json/__init__.py", line 339, in loads
    raise TypeError(f'the JSON object must be str, bytes or bytearray, '
TypeError: the JSON object must be str, bytes or bytearray, not dict

2022-12-01 08:53:14,062 -  nornir.core -     INFO -        run() - Running task 'another_show_command_test' with args {} on 1 hosts
2022-12-01 08:53:48,449 -  nornir.core -     INFO -        run() - Running task 'another_show_command_test' with args {} on 1 hosts
2022-12-01 08:58:09,424 -  nornir.core -     INFO -        run() - Running task 'another_show_command_test' with args {} on 1 hosts
2022-12-01 09:14:56,029 -  nornir.core -     INFO -        run() - Running task 'another_show_command_test' with args {} on 1 hosts
2022-12-01 09:20:00,066 -  nornir.core -     INFO -        run() - Running task 'another_show_command_test' with args {} on 1 hosts
2022-12-01 09:25:25,624 -  nornir.core -     INFO -        run() - Running task 'show_ip_int_br' with args {} on 1 hosts
2022-12-01 09:27:56,574 -  nornir.core -     INFO -        run() - Running task 'show_ip_int_br' with args {} on 1 hosts
2022-12-01 09:46:17,072 -  nornir.core -     INFO -        run() - Running task 'show_ip_int_br' with args {} on 1 hosts
2022-12-01 09:46:17,167 - nornir.core.task -    ERROR -      start() - Host 'R1': task 'netmiko_send_command' failed with traceback:
Traceback (most recent call last):
  File "/home/idansimantov/projects/zero_touch/api/.venv/lib/python3.10/site-packages/nornir/core/task.py", line 99, in start
    r = self.task(self, **self.params)
  File "/home/idansimantov/projects/zero_touch/api/.venv/lib/python3.10/site-packages/nornir_netmiko/tasks/netmiko_send_command.py", line 32, in netmiko_send_command
    result = net_connect.send_command(command_string, **kwargs)
  File "/home/idansimantov/projects/zero_touch/api/.venv/lib/python3.10/site-packages/netmiko/utilities.py", line 592, in wrapper_decorator
    return func(self, *args, **kwargs)
  File "/home/idansimantov/projects/zero_touch/api/.venv/lib/python3.10/site-packages/netmiko/base_connection.py", line 1659, in send_command
    search_pattern = self._prompt_handler(auto_find_prompt)
  File "/home/idansimantov/projects/zero_touch/api/.venv/lib/python3.10/site-packages/netmiko/base_connection.py", line 1544, in _prompt_handler
    prompt = self.find_prompt()
  File "/home/idansimantov/projects/zero_touch/api/.venv/lib/python3.10/site-packages/netmiko/base_connection.py", line 1335, in find_prompt
    self.write_channel(self.RETURN)
  File "/home/idansimantov/projects/zero_touch/api/.venv/lib/python3.10/site-packages/netmiko/base_connection.py", line 97, in wrapper_decorator
    return_val = func(self, *args, **kwargs)
  File "/home/idansimantov/projects/zero_touch/api/.venv/lib/python3.10/site-packages/netmiko/base_connection.py", line 111, in wrapper_decorator
    func(self, out_data)
  File "/home/idansimantov/projects/zero_touch/api/.venv/lib/python3.10/site-packages/netmiko/base_connection.py", line 537, in write_channel
    self.channel.write_channel(out_data)
  File "/home/idansimantov/projects/zero_touch/api/.venv/lib/python3.10/site-packages/netmiko/channel.py", line 74, in write_channel
    self.remote_conn.sendall(write_bytes(out_data, encoding=self.encoding))
  File "/home/idansimantov/projects/zero_touch/api/.venv/lib/python3.10/site-packages/paramiko/channel.py", line 846, in sendall
    sent = self.send(s)
  File "/home/idansimantov/projects/zero_touch/api/.venv/lib/python3.10/site-packages/paramiko/channel.py", line 801, in send
    return self._send(s, m)
  File "/home/idansimantov/projects/zero_touch/api/.venv/lib/python3.10/site-packages/paramiko/channel.py", line 1198, in _send
    raise socket.error("Socket is closed")
OSError: Socket is closed

2022-12-01 09:46:17,170 - nornir.core.task -    ERROR -      start() - Host 'R1': task 'show_ip_int_br' failed with traceback:
Traceback (most recent call last):
  File "/home/idansimantov/projects/zero_touch/api/.venv/lib/python3.10/site-packages/nornir/core/task.py", line 99, in start
    r = self.task(self, **self.params)
  File "/home/idansimantov/projects/zero_touch/api/zero_backend/zero_touch_api/nornir_netmiko_actions.py", line 6, in show_ip_int_br
    interfaces_result = task.run(
  File "/home/idansimantov/projects/zero_touch/api/.venv/lib/python3.10/site-packages/nornir/core/task.py", line 174, in run
    raise NornirSubTaskError(task=run_task, result=r)
nornir.core.exceptions.NornirSubTaskError: Subtask: netmiko_send_command (failed)


2022-12-01 09:46:52,061 -  nornir.core -     INFO -        run() - Running task 'show_ip_int_br' with args {} on 1 hosts
2022-12-01 09:47:38,964 -  nornir.core -     INFO -        run() - Running task 'show_ip_int_br' with args {} on 1 hosts
2022-12-01 09:55:02,297 -  nornir.core -     INFO -        run() - Running task 'show_ip_int_br' with args {} on 1 hosts
2022-12-01 09:57:53,944 -  nornir.core -     INFO -        run() - Running task 'show_ip_int_br' with args {} on 1 hosts
2022-12-06 08:36:48,617 -  nornir.core -     INFO -        run() - Running task 'get_ip' with args {} on 1 hosts
2022-12-06 08:36:51,758 - nornir.core.task -    ERROR -      start() - Host 'R1': task 'netmiko_send_command' failed with traceback:
Traceback (most recent call last):
  File "/home/idansimantov/projects/zero_touch/api/.venv/lib/python3.10/site-packages/netmiko/base_connection.py", line 1046, in establish_connection
    self.remote_conn_pre.connect(**ssh_connect_params)
  File "/home/idansimantov/projects/zero_touch/api/.venv/lib/python3.10/site-packages/paramiko/client.py", line 381, in connect
    raise NoValidConnectionsError(errors)
paramiko.ssh_exception.NoValidConnectionsError: [Errno None] Unable to connect to port 22 on 192.168.19.101

During handling of the above exception, another exception occurred:

Traceback (most recent call last):
  File "/home/idansimantov/projects/zero_touch/api/.venv/lib/python3.10/site-packages/nornir/core/task.py", line 99, in start
    r = self.task(self, **self.params)
  File "/home/idansimantov/projects/zero_touch/api/.venv/lib/python3.10/site-packages/nornir_netmiko/tasks/netmiko_send_command.py", line 26, in netmiko_send_command
    net_connect = task.host.get_connection(CONNECTION_NAME, task.nornir.config)
  File "/home/idansimantov/projects/zero_touch/api/.venv/lib/python3.10/site-packages/nornir/core/inventory.py", line 494, in get_connection
    self.open_connection(
  File "/home/idansimantov/projects/zero_touch/api/.venv/lib/python3.10/site-packages/nornir/core/inventory.py", line 546, in open_connection
    conn_obj.open(
  File "/home/idansimantov/projects/zero_touch/api/.venv/lib/python3.10/site-packages/nornir_netmiko/connections/netmiko.py", line 59, in open
    connection = ConnectHandler(**parameters)
  File "/home/idansimantov/projects/zero_touch/api/.venv/lib/python3.10/site-packages/netmiko/ssh_dispatcher.py", line 365, in ConnectHandler
    return ConnectionClass(*args, **kwargs)
  File "/home/idansimantov/projects/zero_touch/api/.venv/lib/python3.10/site-packages/netmiko/base_connection.py", line 439, in __init__
    self._open()
  File "/home/idansimantov/projects/zero_touch/api/.venv/lib/python3.10/site-packages/netmiko/base_connection.py", line 444, in _open
    self.establish_connection()
  File "/home/idansimantov/projects/zero_touch/api/.venv/lib/python3.10/site-packages/netmiko/base_connection.py", line 1068, in establish_connection
    raise NetmikoTimeoutException(msg)
netmiko.exceptions.NetmikoTimeoutException: TCP connection to device failed.

Common causes of this problem are:
1. Incorrect hostname or IP address.
2. Wrong TCP port.
3. Intermediate firewall blocking access.

Device settings: cisco_ios 192.168.19.101:22



2022-12-06 08:36:51,760 - nornir.core.task -    ERROR -      start() - Host 'R1': task 'get_ip' failed with traceback:
Traceback (most recent call last):
  File "/home/idansimantov/projects/zero_touch/api/.venv/lib/python3.10/site-packages/nornir/core/task.py", line 99, in start
    r = self.task(self, **self.params)
  File "/home/idansimantov/projects/zero_touch/api/zero_backend/zero_touch_api/nornir_netmiko_actions.py", line 27, in get_ip
    response = task.run(
  File "/home/idansimantov/projects/zero_touch/api/.venv/lib/python3.10/site-packages/nornir/core/task.py", line 174, in run
    raise NornirSubTaskError(task=run_task, result=r)
nornir.core.exceptions.NornirSubTaskError: Subtask: netmiko_send_command (failed)


2022-12-09 21:21:12,745 -  nornir.core -     INFO -        run() - Running task 'get_all_ip' with args {} on 1 hosts
2022-12-09 21:21:15,819 - nornir.core.task -    ERROR -      start() - Host 'R1': task 'netmiko_send_command' failed with traceback:
Traceback (most recent call last):
  File "/home/idansimantov/projects/zero_touch/api/.venv/lib/python3.10/site-packages/netmiko/base_connection.py", line 1046, in establish_connection
    self.remote_conn_pre.connect(**ssh_connect_params)
  File "/home/idansimantov/projects/zero_touch/api/.venv/lib/python3.10/site-packages/paramiko/client.py", line 381, in connect
    raise NoValidConnectionsError(errors)
paramiko.ssh_exception.NoValidConnectionsError: [Errno None] Unable to connect to port 22 on 192.168.19.101

During handling of the above exception, another exception occurred:

Traceback (most recent call last):
  File "/home/idansimantov/projects/zero_touch/api/.venv/lib/python3.10/site-packages/nornir/core/task.py", line 99, in start
    r = self.task(self, **self.params)
  File "/home/idansimantov/projects/zero_touch/api/.venv/lib/python3.10/site-packages/nornir_netmiko/tasks/netmiko_send_command.py", line 26, in netmiko_send_command
    net_connect = task.host.get_connection(CONNECTION_NAME, task.nornir.config)
  File "/home/idansimantov/projects/zero_touch/api/.venv/lib/python3.10/site-packages/nornir/core/inventory.py", line 494, in get_connection
    self.open_connection(
  File "/home/idansimantov/projects/zero_touch/api/.venv/lib/python3.10/site-packages/nornir/core/inventory.py", line 546, in open_connection
    conn_obj.open(
  File "/home/idansimantov/projects/zero_touch/api/.venv/lib/python3.10/site-packages/nornir_netmiko/connections/netmiko.py", line 59, in open
    connection = ConnectHandler(**parameters)
  File "/home/idansimantov/projects/zero_touch/api/.venv/lib/python3.10/site-packages/netmiko/ssh_dispatcher.py", line 365, in ConnectHandler
    return ConnectionClass(*args, **kwargs)
  File "/home/idansimantov/projects/zero_touch/api/.venv/lib/python3.10/site-packages/netmiko/base_connection.py", line 439, in __init__
    self._open()
  File "/home/idansimantov/projects/zero_touch/api/.venv/lib/python3.10/site-packages/netmiko/base_connection.py", line 444, in _open
    self.establish_connection()
  File "/home/idansimantov/projects/zero_touch/api/.venv/lib/python3.10/site-packages/netmiko/base_connection.py", line 1068, in establish_connection
    raise NetmikoTimeoutException(msg)
netmiko.exceptions.NetmikoTimeoutException: TCP connection to device failed.

Common causes of this problem are:
1. Incorrect hostname or IP address.
2. Wrong TCP port.
3. Intermediate firewall blocking access.

Device settings: cisco_ios 192.168.19.101:22



2022-12-09 21:21:15,820 - nornir.core.task -    ERROR -      start() - Host 'R1': task 'get_all_ip' failed with traceback:
Traceback (most recent call last):
  File "/home/idansimantov/projects/zero_touch/api/.venv/lib/python3.10/site-packages/nornir/core/task.py", line 99, in start
    r = self.task(self, **self.params)
  File "/home/idansimantov/projects/zero_touch/api/zero_backend/zero_touch_api/nornir_netmiko_actions.py", line 29, in get_all_ip
    response = task.run(
  File "/home/idansimantov/projects/zero_touch/api/.venv/lib/python3.10/site-packages/nornir/core/task.py", line 174, in run
    raise NornirSubTaskError(task=run_task, result=r)
nornir.core.exceptions.NornirSubTaskError: Subtask: netmiko_send_command (failed)


